[2021-01-22 11:42:20,911] {__init__.py:50} INFO - Using executor LocalExecutor
[2021-01-22 11:42:20,912] {dagbag.py:417} INFO - Filling up the DagBag from /opt/airflow/dags
Traceback (most recent call last):
  File "/home/airflow/.local/lib/python3.6/site-packages/sqlalchemy/engine/base.py", line 1277, in _execute_context
    cursor, statement, parameters, context
  File "/home/airflow/.local/lib/python3.6/site-packages/sqlalchemy/engine/default.py", line 593, in do_execute
    cursor.execute(statement, parameters)
psycopg2.errors.UndefinedTable: relation "connection" does not exist
LINE 2: FROM connection GROUP BY connection.conn_id
             ^
The above exception was the direct cause of the following exception:
Traceback (most recent call last):
  File "/home/airflow/.local/bin/airflow", line 37, in <module>
    args.func(args)
  File "/home/airflow/.local/lib/python3.6/site-packages/airflow/utils/cli.py", line 81, in wrapper
    return f(*args, **kwargs)
  File "/home/airflow/.local/lib/python3.6/site-packages/airflow/bin/cli.py", line 1179, in webserver
    app = cached_app_rbac(None) if settings.RBAC else cached_app(None)
  File "/home/airflow/.local/lib/python3.6/site-packages/airflow/www/app.py", line 244, in cached_app
    app = create_app(config, testing)
  File "/home/airflow/.local/lib/python3.6/site-packages/airflow/www/app.py", line 99, in create_app
    from airflow.www import views
  File "/home/airflow/.local/lib/python3.6/site-packages/airflow/www/views.py", line 2504, in <module>
    class ChartModelView(wwwutils.DataProfilingMixin, AirflowModelView):
  File "/home/airflow/.local/lib/python3.6/site-packages/airflow/www/views.py", line 2595, in ChartModelView
    'conn_id': _connection_ids()
  File "/home/airflow/.local/lib/python3.6/site-packages/airflow/utils/db.py", line 74, in wrapper
    return func(*args, **kwargs)
  File "/home/airflow/.local/lib/python3.6/site-packages/airflow/www/views.py", line 2501, in _connection_ids
    .group_by(Connection.conn_id))]
  File "/home/airflow/.local/lib/python3.6/site-packages/sqlalchemy/orm/query.py", line 3535, in __iter__
    return self._execute_and_instances(context)
  File "/home/airflow/.local/lib/python3.6/site-packages/sqlalchemy/orm/query.py", line 3560, in _execute_and_instances
    result = conn.execute(querycontext.statement, self._params)
  File "/home/airflow/.local/lib/python3.6/site-packages/sqlalchemy/engine/base.py", line 1011, in execute
    return meth(self, multiparams, params)
  File "/home/airflow/.local/lib/python3.6/site-packages/sqlalchemy/sql/elements.py", line 298, in _execute_on_connection
    return connection._execute_clauseelement(self, multiparams, params)
  File "/home/airflow/.local/lib/python3.6/site-packages/sqlalchemy/engine/base.py", line 1130, in _execute_clauseelement
    distilled_params,
  File "/home/airflow/.local/lib/python3.6/site-packages/sqlalchemy/engine/base.py", line 1317, in _execute_context
    e, statement, parameters, cursor, context
  File "/home/airflow/.local/lib/python3.6/site-packages/sqlalchemy/engine/base.py", line 1511, in _handle_dbapi_exception
    sqlalchemy_exception, with_traceback=exc_info[2], from_=e
  File "/home/airflow/.local/lib/python3.6/site-packages/sqlalchemy/util/compat.py", line 182, in raise_
    raise exception
  File "/home/airflow/.local/lib/python3.6/site-packages/sqlalchemy/engine/base.py", line 1277, in _execute_context
    cursor, statement, parameters, context
  File "/home/airflow/.local/lib/python3.6/site-packages/sqlalchemy/engine/default.py", line 593, in do_execute
    cursor.execute(statement, parameters)
sqlalchemy.exc.ProgrammingError: (psycopg2.errors.UndefinedTable) relation "connection" does not exist
LINE 2: FROM connection GROUP BY connection.conn_id
             ^
[SQL: SELECT connection.conn_id AS connection_conn_id
FROM connection GROUP BY connection.conn_id]
(Background on this error at: http://sqlalche.me/e/13/f405)
